Workbook

Sheet Ban_Cong_bo
A1: Thông tin Doanh nghiệp
A2: MST tổ chức, cá nhân (*) | C2: Tên sản phẩm (*)
A3: Xuất xứ
A5: Tên nhà sản xuất (*) | C5: Địa chỉ (*)
A6: Điện thoại | C6: Fax
A7: Email | C7: Tên nước xuất xứ (*)
A8: Tên công ty xuất khẩu về Việt Nam | C8: Địa chỉ công ty xuất khẩu về Việt Nam
A9: Thông tin công bố
A11: Số bản công bố (*) | C11: Ngày công bố
A12: Người ký | C12: Phương thức đánh giá phù hợp
A13: Phù hợp với QCKT/QĐATTP | C13: =VLOOKUP(B13,Danh_muc!$A$2:$B$82,2,FALSE) -> #N/A
C14: =VLOOKUP(B14,Danh_muc!$A$2:$B$82,2,FALSE) -> #N/A
C15: =VLOOKUP(B15,Danh_muc!$A$2:$B$82,2,FALSE) -> #N/A
C16: =VLOOKUP(B16,Danh_muc!$A$2:$B$82,2,FALSE) -> #N/A
C17: =VLOOKUP(B17,Danh_muc!$A$2:$B$82,2,FALSE) -> #N/A
C18: =VLOOKUP(B18,Danh_muc!$A$2:$B$82,2,FALSE) -> #N/A
C19: =VLOOKUP(B19,Danh_muc!$A$2:$B$82,2,FALSE) -> #N/A

Sheet Chi_tiet_san_pham
A1: Thông tin chung
A2: Tên nhóm sản phẩm (*) | C2: Số | E2: =VLOOKUP(B2,Danh_muc!$H$2:$I$49,2,FALSE) -> #N/A
A3: Chỉ tiêu cảm quan
A5: Trạng thái | C5: Màu sắc
A6: Mùi vị | C6: Trạng thái đặc trưng khác
A8: Chỉ tiêu chất lượng chủ yếu
A9: Chỉ tiêu vi sinh vật
A10: Hàm lượng kim loại nặng
A11: Hàm lượng hóa chất không mong muốn
A13: Thông tin khác
A14: Các chỉ tiêu khác
A15: Thành phần cấu tạo (*) | C15: Thời hạn sử dụng (*)
A16: Công dụng | C16: Đối tượng sử dụng
A17: Hướng dẫn sử dụng và bảo quản (*) | C17: Chất liệu bao bì và quy cách đóng gói (*)
C18: Quy trình sản xuất
A19: Biện pháp phân biệt thật, giả (nếu có) | C19: Xuất xứ và thương nhân chịu trách nhiệm về chất lượng hàng hóa (*)
A20: Ngày ký | C20: Người ký

Sheet Chi_tieu_chat_luong_chu_yeu
A1: Chỉ tiêu chất lượng chủ yếu
A2: STT | B2: Tên chỉ tiêu (*) | C2: Đơn vị tính (*) | D2: Mức công bố (*) | E2: Mức đáp ứng/khẩu phần ăn | F2: Mã đơn vị tính
F3: =VLOOKUP(C3,Danh_muc!$E$2:$F$38,2) -> #N/A
F4: =VLOOKUP(C4,Danh_muc!$E$2:$F$38,2) -> #N/A
F5: =VLOOKUP(C5,Danh_muc!$E$2:$F$38,2) -> #N/A
F6: =VLOOKUP(C6,Danh_muc!$E$2:$F$38,2) -> #N/A
F7: =VLOOKUP(C7,Danh_muc!$E$2:$F$38,2) -> #N/A
F8: =VLOOKUP(C8,Danh_muc!$E$2:$F$38,2) -> #N/A
F9: =VLOOKUP(C9,Danh_muc!$E$2:$F$38,2) -> #N/A
F10: =VLOOKUP(C10,Danh_muc!$E$2:$F$38,2) -> #N/A
F11: =VLOOKUP(C11,Danh_muc!$E$2:$F$38,2) -> #N/A
F12: =VLOOKUP(C12,Danh_muc!$E$2:$F$38,2) -> #N/A
F13: =VLOOKUP(C13,Danh_muc!$E$2:$F$38,2) -> #N/A
F14: =VLOOKUP(C14,Danh_muc!$E$2:$F$38,2) -> #N/A
... F21: =VLOOKUP(C21,Danh_muc!$E$2:$F$38,2) -> #N/A

Sheet Chi_tieu_vi_sinh_vat
A1: Chỉ tiêu vi sinh vật
A2: STT | B2: Tên chỉ tiêu (*) | C2: Đơn vị tính (*) | D2: Mức tối đa (*) | E2: Mã đơn vị tính
E3: =VLOOKUP(C3,Danh_muc!$E$2:$F$38,2) -> #N/A
E4: =VLOOKUP(C4,Danh_muc!$E$2:$F$38,2) -> #N/A
E5: =VLOOKUP(C5,Danh_muc!$E$2:$F$38,2) -> #N/A
E6: =VLOOKUP(C6,Danh_muc!$E$2:$F$38,2) -> #N/A
E7: =VLOOKUP(C7,Danh_muc!$E$2:$F$38,2) -> #N/A
E8: =VLOOKUP(C8,Danh_muc!$E$2:$F$38,2) -> #N/A
E9: =VLOOKUP(C9,Danh_muc!$E$2:$F$38,2) -> #N/A
E10: =VLOOKUP(C10,Danh_muc!$E$2:$F$38,2) -> #N/A
E11: =VLOOKUP(C11,Danh_muc!$E$2:$F$38,2) -> #N/A
E12: =VLOOKUP(C12,Danh_muc!$E$2:$F$38,2) -> #N/A
E13: =VLOOKUP(C13,Danh_muc!$E$2:$F$38,2) -> #N/A
E14: =VLOOKUP(C14,Danh_muc!$E$2:$F$38,2) -> #N/A
... E21: =VLOOKUP(C21,Danh_muc!$E$2:$F$38,2) -> #N/A

Sheet Ham_luong_kim_loai_nang
A1: Hàm lượng kim loại nặng
A2: STT | B2: Tên chỉ tiêu (*) | C2: Đơn vị tính (*) | D2: Mức tối đa (*) | E2: Mã đơn vị tính
E3: =VLOOKUP(C3,Danh_muc!$E$2:$F$38,2) -> #N/A
E4: =VLOOKUP(C4,Danh_muc!$E$2:$F$38,2) -> #N/A
E5: =VLOOKUP(C5,Danh_muc!$E$2:$F$38,2) -> #N/A
E6: =VLOOKUP(C6,Danh_muc!$E$2:$F$38,2) -> #N/A
E7: =VLOOKUP(C7,Danh_muc!$E$2:$F$38,2) -> #N/A
E8: =VLOOKUP(C8,Danh_muc!$E$2:$F$38,2) -> #N/A
E9: =VLOOKUP(C9,Danh_muc!$E$2:$F$38,2) -> #N/A
E10: =VLOOKUP(C10,Danh_muc!$E$2:$F$38,2) -> #N/A
E11: =VLOOKUP(C11,Danh_muc!$E$2:$F$38,2) -> #N/A
E12: =VLOOKUP(C12,Danh_muc!$E$2:$F$38,2) -> #N/A
E13: =VLOOKUP(C13,Danh_muc!$E$2:$F$38,2) -> #N/A
E14: =VLOOKUP(C14,Danh_muc!$E$2:$F$38,2) -> #N/A
... E21: =VLOOKUP(C21,Danh_muc!$E$2:$F$38,2) -> #N/A

Sheet Ham_luong_hoa_chat
A1: Hàm lượng hóa chất không mong muốn
A2: STT | B2: Tên chỉ tiêu (*) | C2: Đơn vị tính (*) | D2: Mức tối đa (*) | E2: Mã đơn vị tính
E3: =VLOOKUP(C3,Danh_muc!$E$2:$F$38,2) -> #N/A
E4: =VLOOKUP(C4,Danh_muc!$E$2:$F$38,2) -> #N/A
E5: =VLOOKUP(C5,Danh_muc!$E$2:$F$38,2) -> #N/A
E6: =VLOOKUP(C6,Danh_muc!$E$2:$F$38,2) -> #N/A
E7: =VLOOKUP(C7,Danh_muc!$E$2:$F$38,2) -> #N/A
E8: =VLOOKUP(C8,Danh_muc!$E$2:$F$38,2) -> #N/A
E9: =VLOOKUP(C9,Danh_muc!$E$2:$F$38,2) -> #N/A
E10: =VLOOKUP(C10,Danh_muc!$E$2:$F$38,2) -> #N/A
E11: =VLOOKUP(C11,Danh_muc!$E$2:$F$38,2) -> #N/A
E12: =VLOOKUP(C12,Danh_muc!$E$2:$F$38,2) -> #N/A
B14: Thông tin bổ sung | C14: <Dư lượng thuốc bảo vệ thực vật phù hợp với quy định tối đa ô nhiễm sinh học và hóa học trong thực phẩm ban hành kèm theo Quyết định số 46/2007/QĐ-BYT ngày 19/12/2007 của Bộ y tế> | E14: PCT
E15: =VLOOKUP(C15,Danh_muc!$E$2:$F$38,2) -> #N/A
E16: =VLOOKUP(C16,Danh_muc!$E$2:$F$38,2) -> #N/A
E17: =VLOOKUP(C17,Danh_muc!$E$2:$F$38,2) -> #N/A
E18: =VLOOKUP(C18,Danh_muc!$E$2:$F$38,2) -> #N/A
E19: =VLOOKUP(C19,Danh_muc!$E$2:$F$38,2) -> #N/A
E20: =VLOOKUP(C20,Danh_muc!$E$2:$F$38,2) -> #N/A

Sheet Ke_Hoach_Kiem_soat
A1: Kế hoạch kiểm soát chất lượng
A2: STT | B2: Các quá trình sản xuất (*) | C2: Các chỉ tiêu kiểm soát | D2: Quy định kỹ thuật | E2: Tần suất lấy mẫu/cỡ mẫu | F2: Thiết bị thử nghiệm/ kiểm tra | G2: Phương pháp thử/ kiểm tra | H2: Biểu ghi chép | I2: Ghi chú

Sheet Danh_muc
A1: Quy chuẩn kỹ thuật quốc gia | E1: Đơn vị tính | H1: Nhóm sản phẩm | K1: Quốc Gia | L1: Tỉnh/ thành phố
A2: 02/2007/QĐ-BYT | B2: Quyết định 02/2007/QĐ-BYT: Quy định về vệ sinh an toàn đối với sản phẩm thuốc lá | E2: - | F2: - | H2: Bánh các loại | I2: BVK_BB | K2: Afghanistan | L2: An Giang
A3: 19/2012/TT-BYT | B3: 19/2012/TT-BYT - Thông tư Hướng dẫn việc công bố hợp quy và công bố phù hợp quy định an toàn thực phẩm | E3: % | F3: PCT | H3: Bao bì thực phẩm, dụng cụ, vật liệu bao gói, chứa đựng thực phẩm | I3: BBP | K3: Albania | L3: Bắc Cạn
A4: 24/2013/TT-BYT | B4: Thông tư 24/2013/TT-BYT: Quy định mức giới hạn tối đa dư lượng thuốc thú y trong thực phẩm | E4: % (m/m) | F4: % (m/m) | H4: Bơ | I4: SVS_BO | K4: Algeria | L4: Bình Dương
A5: 27/2012/TT-BYT | B5: Thông tư 27/2012/TT-BYT: Hướng dẫn việc quản lý phụ gia thực phẩm | E5: % khối lượng | F5: % khối lượng | H5: Cá đã chế biến | I5: CCB | K5: American Samoa | L5: Bình Định
A6: 3742/2001/QĐ-BYT | B6: 3742/2001/QĐ-BYT: QUYẾT ĐỊNH CỦA BỘ TRƯỞNG BỘ Y TẾ Về việc ban hành Quy định danh mục các chất phụ gia được phép sử dụng trong thực phẩm | E6: % protein | F6: % protein | H6: Các loại vỏ bọc ăn được | I6: TVT_VB | K6: Andorra | L6: Bắc Giang
A7: 38/2012/NĐ-CP | B7: Nghị định số 38/2012/NĐ-CP của Chính phủ : Quy định chi tiết thi hành một số điều của Luật an toàn thực phẩm | E7: % thể tích | F7: % thể tích | H7: Các sản phẩm bánh, kẹo | I7: BVK | K7: Angola | L7: Bạc Liêu
A8: 46/2007/QĐ-BYT | B8: 46/2007/QĐ-BYT: Quy định giới hạn tối đa ô nhiễm sinh học và hóa học trong thực phẩm | E8: %/100g | F8: %/100g | H8: Các sản phẩm dùng để trang trí | I8: BVK_TT | K8: Anguilla | L8: Bắc Ninh
A9: 89/2006/NĐ-CP | B9: Nghị định 89/2006/NĐ-CP: NGHỊ ĐỊNH Về nhãn hàng hóa | E9: %/gói | F9: %/gói | H9: Các sản phẩm tương tự Cacao, Socola | I9: BVK_SC | K9: Antarctica | L9: Bình Phước
A10: QCVN 01:2009/BYT | B10: QCVN 01:2009/BYT: Quy chuẩn kỹ thuật quốc gia về chất lượng nước ăn uống | E10: %/lipid | F10: PPLP | H10: Cacao, socola dạng phết | I10: BVK_CS | K10: Antigua and Barbuda | L10: Bến Tre
A11: QCVN 02:2009/BYT | B11: QCVN 02:2009/BYT: Quy chuẩn kỹ thuật quốc gia về chất lượng nước sinh hoạt | E11: %/viên | F11: perpvien | H11: Chè, cà phê, cacao | I11: CCC | K11: Argentina | L11: Bình Thuận
A12: QCVN 10:2011/BYT | B12: QCVN 10:2011/BYT: Quy chuẩn kỹ thuật quốc gia đối với nước đá dùng liền | E12: %gôm xanthan | F12: pergomxanthan | H12: Cream | I12: SVS_CM | K12: Armenia | L12: Bà rịa-Vũng tàu
A13: QCVN 11-1:2012/BYT | B13: QCVN 11-1:2012/BYT: Quy chuẩn quốc gia đối với sản phẩm dinh dưỡng công thức cho trẻ đến 12 tháng tuổi | E13: %KL | F13: %KL | H13: Dầu và mỡ | I13: DVM | K13: Aruba | L13: Cao Bằng
... A57: QCVN 8-2:2011/BYT | B57: QCVN 8-2:2011/BYT: Quy chuẩn kỹ thuật quốc gia đối với giới hạn ô nhiễm kim loại nặng trong thực phẩm | E57: bào tử/l | F57: bào tửpl | H57: Whey | I57: SVS_WY | K57: Cuba | L57: Thanh Hoá
A58: QCVN 8-3:2011/BYT | B58: QCVN 8-3:2011/BYT: Quy chuẩn kỹ thuật quốc gia đối với ô nhiễm vi sinh vật trong thực phẩm | E58: Bào tử/ml | F58: Bào tử/ml | K58: Cyprus | L58: Thừa Thiên Huế
A59: QCVN 8-3:2012/BYT | B59: QCVN 8-3:2012/BYT: Quy chuẩn kỹ thuật quốc gia về ô nhiễm vi sinh vật trong thực phẩm | E59: bar | F59: bar | K59: Czech Republic | L59: Tiền Giang
A60: QCVN 9-1:2011/BYT | B60: QCVN 9-1:2011/BYT: Quy chuẩn kỹ thuật quốc gia đối với muối Iod | E60: BGF/g | F60: BGF/g | K60: Denmark | L60: Tuyên Quang
A61: QCVN 9-2:2011/BYT | B61: QCVN 9-2:2011/BYT: Quy chuẩn kỹ thuật quốc gia đối với thực phẩm bổ sung vi chất dinh dưỡng (đối với sản phẩm nước mắm, bột mỳ, dầu ăn, đường bổ sung vi chất) | E61: BGLU/g | F61: BGLU/g | K61: Djibouti | L61: Trà Vinh
A62: TCVN 3974:2007 | B62: TCVN 3974:2007: Muối thực phẩm | E62: Bq/l | F62: BQPLT | K62: Dominica | L62: Vĩnh Long
A63: TCVN 5908:2009 | B63: Tiêu chuẩn quốc gia TCVN 5908 : 2009 về KẸO (Candy) | E63: Brix | F63: Brix | K63: Dominican Republic | L63: Vĩnh Phúc
E64: BT/g | F64: BTpg | K64: East Timor | L64: Yên Bái
E65: BT/ml | F65: BT/ml | K65: Ecuador
E66: BU | F66: BU | K66: Egypt
E67: cal/200ml | F67: cal/200ml | K67: El Salvador
E68: cc/m2/ngày | F68: cc/m2/ngày | K68: Equitorial Guinea
E69: CFU/ gói 3g | F69: CFU/ gói 3g | K69: Eritrea
E70: cfu/0,1g | F70: cfu/0,1g | K70: Estonia
E71: CFU/100g | F71: CFU/100g | K71: Ethiopia
E72: cfu/10g | F72: cfu/10g | K72: Falkland Islands (Islas Malvinas)
E73: CFU/10mg | F73: CFU/10mg | K73: Faroe Islands
E74: CFU/10ml | F74: CFUp10ml | K74: Fiji
E75: cfu/125g | F75: cfu/125g | K75: Finland
E76: Cfu/1g | F76: Cfu/1g | K76: France
... E245: IU/100ml | F245: IUp100ml | K245: Zimbabwe
E246: IU/10ml | F246: IUp10ml
E247: IU/120ml | F247: IU/120ml
E248: IU/125ml | F248: IU/125ml
E249: IU/150ml | F249: IU/150ml
E250: IU/15ml | F250: IU/15ml
E251: IU/17g | F251: IUP17g
...
